<mujoco model="arm3d">
    <compiler angle="radian" coordinate="local" inertiafromgeom="true" />
    <option gravity="0 0 0" integrator="Euler" iterations="20" timestep="0.01" />
    <asset>
        <texture file="table/wood-texture/pic_040.png" name="table_texture" type="2d" />
        <material name="table_material" shininess="0.1" specular="0.4" texrepeat="1 1" texture="table_texture" />
    </asset>
    
    <default>
        <joint armature="0.04" damping="1" limited="true" />
        <geom conaffinity="1" condim="1" contype="1" density="300" friction="1.8 .1 .1" margin="0.002" />
    </default>
    
    <worldbody>
        <light diffuse=".9 .9 .9" dir="0 0 -1" pos="0 0 5" />
        <geom conaffinity="1" contype="1" material="table_material" pos="0 0.5 -0.15" size="2 4 0.1" type="plane" />

        <body name="palm" pos="2. 0.5 0.2">
            <geom fromto="0 0 -0.1 0 0 0.1" rgba="0.14117647 0.17647059 0.0. 0. 0. 1." size="0.12" type="capsule" />
            <body axisangle="0 0 1 -0.385" name="proximal_1" pos="0 0 -0.075">
                <joint axis="0 0 1" damping="1.0" name="proximal_j_1" pos="0 0 0" range="-3.0 3.0" type="hinge" />
                <geom conaffinity="1" contype="1" fromto="0 0 0 -0.8 0 0" rgba="0. 0. 0. 1." size="0.03" type="capsule" />
                <body axisangle="0 0 1 0.385" name="distal_1" pos="-0.8 0 0">
                    <joint axis="0 0 1" damping="1.0" name="distal_j_1" pos="0 0 0" range="-3.5 3.5" type="hinge" />
                    <geom conaffinity="1" contype="1" fromto="0 0 0 -0.8 0 0" rgba="0. 0. 0. 1." size="0.03" type="capsule" />
                    <body name="distal_2" pos="-0.8 0 0">
                        <joint axis="0 0 1" damping="1.0" name="distal_j_2" pos="0 0 0" range="-2.0 2.0" type="hinge" />
                        <geom conaffinity="1" contype="1" fromto="0 0 0 -0.8 0 0" rgba="0. 0. 0. 1." size="0.03" type="capsule" />
                        <body name="distal_4" pos="-0.8 0 0">
                            <site name="tip arml" pos="0.4 0 -0.12" size="0.01" />
                            <site name="tip armr" pos="0 0 -0.12" size="0.01" />
                            
                            <geom conaffinity="1" contype="1" pos="0.4 0 -0.12" rgba="0. 0. 0. 1." size="0.4 0.02 0.12" type="box" />
                        </body>
                    </body>
                </body>
            </body>
        </body>




        <body name="goal" pos="0 -0.5 -0.145">
            
            
            <geom conaffinity="0" contype="0" density="0.00001" rgba="1. 1. 1. 1" size="0.42 0.24 0.01" type="box" />
            <geom conaffinity="1" contype="1" density="1000" pos="-0.42 0 0.1" rgba="1. 1. 1. 1" size="0.04 0.24 0.1" type="box" />
            <geom conaffinity="1" contype="1" density="1000" pos="0.42 0 0.1" rgba="1. 1. 1. 1" size="0.04 0.24 0.1" type="box" />
            <geom conaffinity="1" contype="1" density="1000" pos="0. -0.20 0.1" rgba="1. 1. 1. 1" size="0.42 0.04 0.1" type="box" />
            <geom conaffinity="1" contype="1" density="1000" pos="0. -0.50 0.14" rgba="1. 1. 1. 1" size="0.06 0.3 0.06" type="box" />

            
            <joint axis="0 1 0" damping="0.5" name="goal_slidey" pos="0 0 0" range="-10.3213 10.3" type="slide" />
            <joint axis="1 0 0" damping="0.5" name="goal_slidex" pos="0 0 0" range="-10.3213 10.3" type="slide" /> 
        </body>

    <body name="object0" pos="0.032280 0.113529 -0.08"><geom conaffinity="1" contype="1" density="0.001" rgba="0.2 0.2 0.2 1" size="0.05" type="sphere" /><joint axis="0 1 0" damping="0.5" name="object0_slidey" pos="0.025 0.025 0.025" range="-10.3213 10.3" type="slide" /><joint axis="1 0 0" name="object0_slidex" pos="0.025 0.025 0.025" range="-10.3213 10.3" type="slide" /></body><body name="object1" pos="-0.121549 -0.077676 -0.08"><geom conaffinity="1" contype="1" density="0.001" rgba="0.2 0.2 0.2 1" size="0.05" type="sphere" /><joint axis="0 1 0" damping="0.5" name="object1_slidey" pos="0.025 0.025 0.025" range="-10.3213 10.3" type="slide" /><joint axis="1 0 0" name="object1_slidex" pos="0.025 0.025 0.025" range="-10.3213 10.3" type="slide" /></body><body name="object2" pos="0.077668 -0.117487 -0.08"><geom conaffinity="1" contype="1" density="0.001" rgba="0.2 0.2 0.2 1" size="0.05" type="sphere" /><joint axis="0 1 0" damping="0.5" name="object2_slidey" pos="0.025 0.025 0.025" range="-10.3213 10.3" type="slide" /><joint axis="1 0 0" name="object2_slidex" pos="0.025 0.025 0.025" range="-10.3213 10.3" type="slide" /></body><body name="object3" pos="-0.068240 0.077765 -0.08"><geom conaffinity="1" contype="1" density="0.001" rgba="0.2 0.2 0.2 1" size="0.05" type="sphere" /><joint axis="0 1 0" damping="0.5" name="object3_slidey" pos="0.025 0.025 0.025" range="-10.3213 10.3" type="slide" /><joint axis="1 0 0" name="object3_slidex" pos="0.025 0.025 0.025" range="-10.3213 10.3" type="slide" /></body><body name="object4" pos="-0.018652 0.068177 -0.08"><geom conaffinity="1" contype="1" density="0.001" rgba="0.2 0.2 0.2 1" size="0.05" type="sphere" /><joint axis="0 1 0" damping="0.5" name="object4_slidey" pos="0.025 0.025 0.025" range="-10.3213 10.3" type="slide" /><joint axis="1 0 0" name="object4_slidex" pos="0.025 0.025 0.025" range="-10.3213 10.3" type="slide" /></body></worldbody>

    <actuator>
        <motor ctrllimited="true" ctrlrange="-3 3" joint="proximal_j_1" />
        <motor ctrllimited="true" ctrlrange="-3 3" joint="distal_j_1" />
        <motor ctrllimited="true" ctrlrange="-3 3" joint="distal_j_2" />
        
    </actuator>
</mujoco>